2025-03-15 19:42:18,220 INFO    MainThread:89305 [wandb_setup.py:_flush():67] Current SDK version is 0.19.7
2025-03-15 19:42:18,220 INFO    MainThread:89305 [wandb_setup.py:_flush():67] Configure stats pid to 89305
2025-03-15 19:42:18,220 INFO    MainThread:89305 [wandb_setup.py:_flush():67] Loading settings from /Users/verisimilitude/.config/wandb/settings
2025-03-15 19:42:18,220 INFO    MainThread:89305 [wandb_setup.py:_flush():67] Loading settings from /Volumes/T9/EpiMECoV/wandb/settings
2025-03-15 19:42:18,220 INFO    MainThread:89305 [wandb_setup.py:_flush():67] Loading settings from environment variables
2025-03-15 19:42:18,220 INFO    MainThread:89305 [wandb_init.py:setup_run_log_directory():647] Logging user logs to /Volumes/T9/EpiMECoV/wandb/run-20250315_194217-z3tykvs2/logs/debug.log
2025-03-15 19:42:18,220 INFO    MainThread:89305 [wandb_init.py:setup_run_log_directory():648] Logging internal logs to /Volumes/T9/EpiMECoV/wandb/run-20250315_194217-z3tykvs2/logs/debug-internal.log
2025-03-15 19:42:18,220 INFO    MainThread:89305 [wandb_init.py:init():761] calling init triggers
2025-03-15 19:42:18,220 INFO    MainThread:89305 [wandb_init.py:init():766] wandb.init called with sweep_config: {}
config: {'chunk_size': 1000, 'batch_size': 8, 'pretrain_epochs': 30, 'finetune_epochs': 100, 'learning_rate': 0.0001, 'model_dim': 256, 'ff_dim': 1024, 'n_layers': 6, 'num_heads': 8, 'dropout': 0.2, 'moe_experts': 4, 'lora_r': 8, 'architecture': 'SOTA Transformer with ALiBi + LoRA + MoE', '_wandb': {}}
2025-03-15 19:42:18,220 INFO    MainThread:89305 [wandb_init.py:init():784] starting backend
2025-03-15 19:42:18,220 INFO    MainThread:89305 [wandb_init.py:init():788] sending inform_init request
2025-03-15 19:42:18,243 INFO    MainThread:89305 [backend.py:_multiprocessing_setup():97] multiprocessing start_methods=spawn,fork,forkserver, using: spawn
2025-03-15 19:42:18,243 INFO    MainThread:89305 [wandb_init.py:init():803] backend started and connected
2025-03-15 19:42:18,244 INFO    MainThread:89305 [wandb_init.py:init():896] updated telemetry
2025-03-15 19:42:18,300 INFO    MainThread:89305 [wandb_init.py:init():920] communicating run to backend with 90.0 second timeout
2025-03-15 19:42:18,686 INFO    MainThread:89305 [wandb_init.py:init():995] starting run threads in backend
2025-03-15 19:42:18,868 INFO    MainThread:89305 [wandb_run.py:_console_start():2377] atexit reg
2025-03-15 19:42:18,869 INFO    MainThread:89305 [wandb_run.py:_redirect():2227] redirect: wrap_raw
2025-03-15 19:42:18,869 INFO    MainThread:89305 [wandb_run.py:_redirect():2292] Wrapping output streams.
2025-03-15 19:42:18,869 INFO    MainThread:89305 [wandb_run.py:_redirect():2317] Redirects installed.
2025-03-15 19:42:18,870 INFO    MainThread:89305 [wandb_init.py:init():1037] run started, returning control to user process
2025-03-15 19:42:18,871 WARNING MsgRouterThr:89305 [router.py:message_loop():77] message_loop has been closed
Traceback (most recent call last):
  File "/opt/homebrew/lib/python3.12/site-packages/wandb/sdk/interface/router_sock.py", line 28, in _read_message
    resp = self._sock_client.read_server_response(timeout=1)
           ^^^^^^^^^^^^^^^^^^^^^^^^^^^^^^^^^^^^^^^^^^^^^^^^^
  File "/opt/homebrew/lib/python3.12/site-packages/wandb/sdk/lib/sock_client.py", line 285, in read_server_response
    data = self._read_packet_bytes(timeout=timeout)
           ^^^^^^^^^^^^^^^^^^^^^^^^^^^^^^^^^^^^^^^^
  File "/opt/homebrew/lib/python3.12/site-packages/wandb/sdk/lib/sock_client.py", line 270, in _read_packet_bytes
    raise SockClientClosedError
wandb.sdk.lib.sock_client.SockClientClosedError

The above exception was the direct cause of the following exception:

Traceback (most recent call last):
  File "/opt/homebrew/lib/python3.12/site-packages/wandb/sdk/interface/router.py", line 70, in message_loop
    msg = self._read_message()
          ^^^^^^^^^^^^^^^^^^^^
  File "/opt/homebrew/lib/python3.12/site-packages/wandb/sdk/interface/router_sock.py", line 30, in _read_message
    raise MessageRouterClosedError from e
wandb.sdk.interface.router.MessageRouterClosedError
2025-03-15 19:42:18,872 INFO    MsgRouterThr:89305 [mailbox.py:close():115] Closing mailbox, abandoning 3 handles.
